Workbook
Name Slicer_Department: #N/A
Name Slicer_Employment_Status: #N/A
Name Slicer_Employment_Year: #N/A
Name Slicer_Performance_Band: #N/A

Sheet Raw_Employee_Data
B1: Emp ID | C1: Full_Name | D1: Dept_Code | E1: Department | F1: Hire Date | G1: Employment Year | H1: Salary | I1: Perf_Score | J1: Years of Service | K1: Performance_Band | L1: Bonus_Percentage | M1: Eligible Bonus Amount | N1: Employment Status | O1: Column2
B2: EMP127 | C2: Emily Brown | D2: IT02 | E2: =_xlfn.XLOOKUP(D2,Lookup_Departments!$A$2:$A$7,Lookup_Departments!$B$2:$B$7,"Invalid Dept_Code",0) -> Information Technology | F2: 43093 | G2: =TEXT(Table1[[#This Row],[Hire Date ]],"yyyy") -> 2017 | H2: 50361 | I2: 52 | J2: =DATEDIF(F2,TODAY(),"Y") -> 8 | K2: {=_xlfn.IFS(I2<=49,"Needs Improvement",I2<=69,"Developing",I2<=84,"Achieving",I2<=94,"Exceeding",I2<=100,"Outstanding")} -> Developing | L2: =_xlfn.XLOOKUP(K2,Lookup_Performance!$C$2:$C$6,Lookup_Performance!$D$2:$D$6,"N/A",0) -> 0.02 | M2: =H2*L2 -> 1007.22 | N2: Active | O2: =TRIM(CLEAN(Table1[[#This Row],[Employment Status]])) -> Active
B3: EMP046 | C3: Richard Hernandez | D3: MKT04 | E3: =_xlfn.XLOOKUP(D3,Lookup_Departments!$A$2:$A$7,Lookup_Departments!$B$2:$B$7,"Invalid Dept_Code",0) -> Marketing | F3: 44659 | G3: =TEXT(Table1[[#This Row],[Hire Date ]],"yyyy") -> 2022 | H3: 112673 | I3: 68 | J3: =DATEDIF(F3,TODAY(),"Y") -> 4 | K3: {=_xlfn.IFS(I3<=49,"Needs Improvement",I3<=69,"Developing",I3<=84,"Achieving",I3<=94,"Exceeding",I3<=100,"Outstanding")} -> Developing | L3: =_xlfn.XLOOKUP(K3,Lookup_Performance!$C$2:$C$6,Lookup_Performance!$D$2:$D$6,"N/A",0) -> 0.02 | M3: =H3*L3 -> 2253.46 | N3: Active | O3: =TRIM(CLEAN(Table1[[#This Row],[Employment Status]])) -> Active
B4: EMP134 | C4: Emily Gonzalez | D4: IT02 | E4: =_xlfn.XLOOKUP(D4,Lookup_Departments!$A$2:$A$7,Lookup_Departments!$B$2:$B$7,"Invalid Dept_Code",0) -> Information Technology | F4: 42431 | G4: =TEXT(Table1[[#This Row],[Hire Date ]],"yyyy") -> 2016 | H4: 114425 | I4: 54 | J4: =DATEDIF(F4,TODAY(),"Y") -> 10 | K4: {=_xlfn.IFS(I4<=49,"Needs Improvement",I4<=69,"Developing",I4<=84,"Achieving",I4<=94,"Exceeding",I4<=100,"Outstanding")} -> Developing | L4: =_xlfn.XLOOKUP(K4,Lookup_Performance!$C$2:$C$6,Lookup_Performance!$D$2:$D$6,"N/A",0) -> 0.02 | M4: =H4*L4 -> 2288.5 | N4: Left | O4: =TRIM(CLEAN(Table1[[#This Row],[Employment Status]])) -> Left
B5: EMP139 | C5: John Martinez | D5: FIN03 | E5: =_xlfn.XLOOKUP(D5,Lookup_Departments!$A$2:$A$7,Lookup_Departments!$B$2:$B$7,"Invalid Dept_Code",0) -> Finance | F5: 45110 | G5: =TEXT(Table1[[#This Row],[Hire Date ]],"yyyy") -> 2023 | H5: 103831 | I5: 70 | J5: =DATEDIF(F5,TODAY(),"Y") -> 3 | K5: {=_xlfn.IFS(I5<=49,"Needs Improvement",I5<=69,"Developing",I5<=84,"Achieving",I5<=94,"Exceeding",I5<=100,"Outstanding")} -> Achieving | L5: =_xlfn.XLOOKUP(K5,Lookup_Performance!$C$2:$C$6,Lookup_Performance!$D$2:$D$6,"N/A",0) -> 0.05 | M5: =H5*L5 -> 5191.55 | N5: Active | O5: =TRIM(CLEAN(Table1[[#This Row],[Employment Status]])) -> Active
B6: EMP112 | C6: Thomas Smith | D6: IT02 | E6: =_xlfn.XLOOKUP(D6,Lookup_Departments!$A$2:$A$7,Lookup_Departments!$B$2:$B$7,"Invalid Dept_Code",0) -> Information Technology | F6: 44977 | G6: =TEXT(Table1[[#This Row],[Hire Date ]],"yyyy") -> 2023 | H6: 73785 | I6: 40 | J6: =DATEDIF(F6,TODAY(),"Y") -> 3 | K6: {=_xlfn.IFS(I6<=49,"Needs Improvement",I6<=69,"Developing",I6<=84,"Achieving",I6<=94,"Exceeding",I6<=100,"Outstanding")} -> Needs Improvement | L6: =_xlfn.XLOOKUP(K6,Lookup_Performance!$C$2:$C$6,Lookup_Performance!$D$2:$D$6,"N/A",0) -> 0 | M6: =H6*L6 -> 0 | N6: Left | O6: =TRIM(CLEAN(Table1[[#This Row],[Employment Status]])) -> Left
B7: EMP030 | C7: Emily Johnson | D7: OPS06 | E7: =_xlfn.XLOOKUP(D7,Lookup_Departments!$A$2:$A$7,Lookup_Departments!$B$2:$B$7,"Invalid Dept_Code",0) -> Operations | F7: 43892 | G7: =TEXT(Table1[[#This Row],[Hire Date ]],"yyyy") -> 2020 | H7: 115882 | I7: 49 | J7: =DATEDIF(F7,TODAY(),"Y") -> 6 | K7: {=_xlfn.IFS(I7<=49,"Needs Improvement",I7<=69,"Developing",I7<=84,"Achieving",I7<=94,"Exceeding",I7<=100,"Outstanding")} -> Needs Improvement | L7: =_xlfn.XLOOKUP(K7,Lookup_Performance!$C$2:$C$6,Lookup_Performance!$D$2:$D$6,"N/A",0) -> 0 | M7: =H7*L7 -> 0 | N7: Active | O7: =TRIM(CLEAN(Table1[[#This Row],[Employment Status]])) -> Active
B8: EMP096 | C8: John Wilson | D8: OPS06 | E8: =_xlfn.XLOOKUP(D8,Lookup_Departments!$A$2:$A$7,Lookup_Departments!$B$2:$B$7,"Invalid Dept_Code",0) -> Operations | F8: 45272 | G8: =TEXT(Table1[[#This Row],[Hire Date ]],"yyyy") -> 2023 | H8: 59980 | I8: 70 | J8: =DATEDIF(F8,TODAY(),"Y") -> 2 | K8: {=_xlfn.IFS(I8<=49,"Needs Improvement",I8<=69,"Developing",I8<=84,"Achieving",I8<=94,"Exceeding",I8<=100,"Outstanding")} -> Achieving | L8: =_xlfn.XLOOKUP(K8,Lookup_Performance!$C$2:$C$6,Lookup_Performance!$D$2:$D$6,"N/A",0) -> 0.05 | M8: =H8*L8 -> 2999 | N8: Left | O8: =TRIM(CLEAN(Table1[[#This Row],[Employment Status]])) -> Left
B9: EMP098 | C9: Jessica Smith | D9: OPS06 | E9: =_xlfn.XLOOKUP(D9,Lookup_Departments!$A$2:$A$7,Lookup_Departments!$B$2:$B$7,"Invalid Dept_Code",0) -> Operations | F9: 44174 | G9: =TEXT(Table1[[#This Row],[Hire Date ]],"yyyy") -> 2020 | H9: 68728 | I9: 45 | J9: =DATEDIF(F9,TODAY(),"Y") -> 5 | K9: {=_xlfn.IFS(I9<=49,"Needs Improvement",I9<=69,"Developing",I9<=84,"Achieving",I9<=94,"Exceeding",I9<=100,"Outstanding")} -> Needs Improvement | L9: =_xlfn.XLOOKUP(K9,Lookup_Performance!$C$2:$C$6,Lookup_Performance!$D$2:$D$6,"N/A",0) -> 0 | M9: =H9*L9 -> 0 | N9: Active | O9: =TRIM(CLEAN(Table1[[#This Row],[Employment Status]])) -> Active
B10: EMP095 | C10: Rodriguez | D10: FIN03 | E10: =_xlfn.XLOOKUP(D10,Lookup_Departments!$A$2:$A$7,Lookup_Departments!$B$2:$B$7,"Invalid Dept_Code",0) -> Finance | F10: 43107 | G10: =TEXT(Table1[[#This Row],[Hire Date ]],"yyyy") -> 2018 | H10: 102139 | I10: 79 | J10: =DATEDIF(F10,TODAY(),"Y") -> 8 | K10: {=_xlfn.IFS(I10<=49,"Needs Improvement",I10<=69,"Developing",I10<=84,"Achieving",I10<=94,"Exceeding",I10<=100,"Outstanding")} -> Achieving | L10: =_xlfn.XLOOKUP(K10,Lookup_Performance!$C$2:$C$6,Lookup_Performance!$D$2:$D$6,"N/A",0) -> 0.05 | M10: =H10*L10 -> 5106.95 | N10: Active | O10: =TRIM(CLEAN(Table1[[#This Row],[Employment Status]])) -> Active
B11: EMP140 | C11: Michael Martinez | D11: SAL05 | E11: =_xlfn.XLOOKUP(D11,Lookup_Departments!$A$2:$A$7,Lookup_Departments!$B$2:$B$7,"Invalid Dept_Code",0) -> Sales | F11: 42676 | G11: =TEXT(Table1[[#This Row],[Hire Date ]],"yyyy") -> 2016 | H11: 94998 | I11: 58 | J11: =DATEDIF(F11,TODAY(),"Y") -> 9 | K11: {=_xlfn.IFS(I11<=49,"Needs Improvement",I11<=69,"Developing",I11<=84,"Achieving",I11<=94,"Exceeding",I11<=100,"Outstanding")} -> Developing | L11: =_xlfn.XLOOKUP(K11,Lookup_Performance!$C$2:$C$6,Lookup_Performance!$D$2:$D$6,"N/A",0) -> 0.02 | M11: =H11*L11 -> 1899.96 | N11: Active | O11: =TRIM(CLEAN(Table1[[#This Row],[Employment Status]])) -> Active
B12: EMP020 | C12: Emily Miller | D12: SAL05 | E12: =_xlfn.XLOOKUP(D12,Lookup_Departments!$A$2:$A$7,Lookup_Departments!$B$2:$B$7,"Invalid Dept_Code",0) -> Sales | F12: 43911 | G12: =TEXT(Table1[[#This Row],[Hire Date ]],"yyyy") -> 2020 | H12: 118635 | I12: 49 | J12: =DATEDIF(F12,TODAY(),"Y") -> 6 | K12: {=_xlfn.IFS(I12<=49,"Needs Improvement",I12<=69,"Developing",I12<=84,"Achieving",I12<=94,"Exceeding",I12<=100,"Outstanding")} -> Needs Improvement | L12: =_xlfn.XLOOKUP(K12,Lookup_Performance!$C$2:$C$6,Lookup_Performance!$D$2:$D$6,"N/A",0) -> 0 | M12: =H12*L12 -> 0 | N12: Active | O12: =TRIM(CLEAN(Table1[[#This Row],[Employment Status]])) -> Active
B13: EMP057 | C13: Emily Hernandez | D13: IT02 | E13: =_xlfn.XLOOKUP(D13,Lookup_Departments!$A$2:$A$7,Lookup_Departments!$B$2:$B$7,"Invalid Dept_Code",0) -> Information Technology | F13: 42425 | G13: =TEXT(Table1[[#This Row],[Hire Date ]],"yyyy") -> 2016 | H13: 76918 | I13: 62 | J13: =DATEDIF(F13,TODAY(),"Y") -> 10 | K13: {=_xlfn.IFS(I13<=49,"Needs Improvement",I13<=69,"Developing",I13<=84,"Achieving",I13<=94,"Exceeding",I13<=100,"Outstanding")} -> Developing | L13: =_xlfn.XLOOKUP(K13,Lookup_Performance!$C$2:$C$6,Lookup_Performance!$D$2:$D$6,"N/A",0) -> 0.02 | M13: =H13*L13 -> 1538.36 | N13: Active | O13: =TRIM(CLEAN(Table1[[#This Row],[Employment Status]])) -> Active
... B38: EMP043 | C38: John Wilson | D38: OPS06 | E38: =_xlfn.XLOOKUP(D38,Lookup_Departments!$A$2:$A$7,Lookup_Departments!$B$2:$B$7,"Invalid Dept_Code",0) -> Operations | F38: 44776 | G38: =TEXT(Table1[[#This Row],[Hire Date ]],"yyyy") -> 2022 | H38: 111845 | I38: 98 | J38: =DATEDIF(F38,TODAY(),"Y") -> 3 | K38: {=_xlfn.IFS(I38<=49,"Needs Improvement",I38<=69,"Developing",I38<=84,"Achieving",I38<=94,"Exceeding",I38<=100,"Outstanding")} -> Outstanding | L38: =_xlfn.XLOOKUP(K38,Lookup_Performance!$C$2:$C$6,Lookup_Performance!$D$2:$D$6,"N/A",0) -> 0.12 | M38: =H38*L38 -> 13421.4 | N38: Active | O38: =TRIM(CLEAN(Table1[[#This Row],[Employment Status]])) -> Active
B39: EMP068 | C39: Melissa Brown | D39: SAL05 | E39: =_xlfn.XLOOKUP(D39,Lookup_Departments!$A$2:$A$7,Lookup_Departments!$B$2:$B$7,"Invalid Dept_Code",0) -> Sales | F39: 06/29/2022 | G39: =TEXT(Table1[[#This Row],[Hire Date ]],"yyyy") -> 2022 | H39: 69219 | I39: 93 | J39: =DATEDIF(F39,TODAY(),"Y") -> 4 | K39: {=_xlfn.IFS(I39<=49,"Needs Improvement",I39<=69,"Developing",I39<=84,"Achieving",I39<=94,"Exceeding",I39<=100,"Outstanding")} -> Exceeding | L39: =_xlfn.XLOOKUP(K39,Lookup_Performance!$C$2:$C$6,Lookup_Performance!$D$2:$D$6,"N/A",0) -> 0.08 | M39: =H39*L39 -> 5537.52 | N39: Active | O39: =TRIM(CLEAN(Table1[[#This Row],[Employment Status]])) -> Active
B40: EMP128 | C40: Michael Smith | D40: FIN03 | E40: =_xlfn.XLOOKUP(D40,Lookup_Departments!$A$2:$A$7,Lookup_Departments!$B$2:$B$7,"Invalid Dept_Code",0) -> Finance | F40: 43949 | G40: =TEXT(Table1[[#This Row],[Hire Date ]],"yyyy") -> 2020 | H40: 95315 | I40: 80 | J40: =DATEDIF(F40,TODAY(),"Y") -> 6 | K40: {=_xlfn.IFS(I40<=49,"Needs Improvement",I40<=69,"Developing",I40<=84,"Achieving",I40<=94,"Exceeding",I40<=100,"Outstanding")} -> Achieving | L40: =_xlfn.XLOOKUP(K40,Lookup_Performance!$C$2:$C$6,Lookup_Performance!$D$2:$D$6,"N/A",0) -> 0.05 | M40: =H40*L40 -> 4765.75 | N40: Left | O40: =TRIM(CLEAN(Table1[[#This Row],[Employment Status]])) -> Left
B41: EMP027 | C41: Sarah Miller | D41: OPS06 | E41: =_xlfn.XLOOKUP(D41,Lookup_Departments!$A$2:$A$7,Lookup_Departments!$B$2:$B$7,"Invalid Dept_Code",0) -> Operations | F41: 09/09/2017 | G41: =TEXT(Table1[[#This Row],[Hire Date ]],"yyyy") -> 2017 | H41: 57514 | I41: 68 | J41: =DATEDIF(F41,TODAY(),"Y") -> 8 | K41: {=_xlfn.IFS(I41<=49,"Needs Improvement",I41<=69,"Developing",I41<=84,"Achieving",I41<=94,"Exceeding",I41<=100,"Outstanding")} -> Developing | L41: =_xlfn.XLOOKUP(K41,Lookup_Performance!$C$2:$C$6,Lookup_Performance!$D$2:$D$6,"N/A",0) -> 0.02 | M41: =H41*L41 -> 1150.28 | N41: Active | O41: =TRIM(CLEAN(Table1[[#This Row],[Employment Status]])) -> Active
B42: EMP136 | C42: Emily Wilson | D42: SAL05 | E42: =_xlfn.XLOOKUP(D42,Lookup_Departments!$A$2:$A$7,Lookup_Departments!$B$2:$B$7,"Invalid Dept_Code",0) -> Sales | F42: 43181 | G42: =TEXT(Table1[[#This Row],[Hire Date ]],"yyyy") -> 2018 | H42: 86245 | I42: 71 | J42: =DATEDIF(F42,TODAY(),"Y") -> 8 | K42: {=_xlfn.IFS(I42<=49,"Needs Improvement",I42<=69,"Developing",I42<=84,"Achieving",I42<=94,"Exceeding",I42<=100,"Outstanding")} -> Achieving | L42: =_xlfn.XLOOKUP(K42,Lookup_Performance!$C$2:$C$6,Lookup_Performance!$D$2:$D$6,"N/A",0) -> 0.05 | M42: =H42*L42 -> 4312.25 | N42: Left | O42: =TRIM(CLEAN(Table1[[#This Row],[Employment Status]])) -> Left
B43: EMP079 | C43: David Hernandez | D43: SAL05 | E43: =_xlfn.XLOOKUP(D43,Lookup_Departments!$A$2:$A$7,Lookup_Departments!$B$2:$B$7,"Invalid Dept_Code",0) -> Sales | F43: 43958 | G43: =TEXT(Table1[[#This Row],[Hire Date ]],"yyyy") -> 2020 | H43: 52407 | I43: 55 | J43: =DATEDIF(F43,TODAY(),"Y") -> 6 | K43: {=_xlfn.IFS(I43<=49,"Needs Improvement",I43<=69,"Developing",I43<=84,"Achieving",I43<=94,"Exceeding",I43<=100,"Outstanding")} -> Developing | L43: =_xlfn.XLOOKUP(K43,Lookup_Performance!$C$2:$C$6,Lookup_Performance!$D$2:$D$6,"N/A",0) -> 0.02 | M43: =H43*L43 -> 1048.14 | N43: Active | O43: =TRIM(CLEAN(Table1[[#This Row],[Employment Status]])) -> Active
B44: EMP149 | C44: James Smith | D44: OPS06 | E44: =_xlfn.XLOOKUP(D44,Lookup_Departments!$A$2:$A$7,Lookup_Departments!$B$2:$B$7,"Invalid Dept_Code",0) -> Operations | F44: 43549 | G44: =TEXT(Table1[[#This Row],[Hire Date ]],"yyyy") -> 2019 | H44: 66606 | I44: 93 | J44: =DATEDIF(F44,TODAY(),"Y") -> 7 | K44: {=_xlfn.IFS(I44<=49,"Needs Improvement",I44<=69,"Developing",I44<=84,"Achieving",I44<=94,"Exceeding",I44<=100,"Outstanding")} -> Exceeding | L44: =_xlfn.XLOOKUP(K44,Lookup_Performance!$C$2:$C$6,Lookup_Performance!$D$2:$D$6,"N/A",0) -> 0.08 | M44: =H44*L44 -> 5328.48 | N44: Resigned | O44: =TRIM(CLEAN(Table1[[#This Row],[Employment Status]])) -> Resigned
B45: EMP037 | C45: Sarah Williams | D45: IT02 | E45: =_xlfn.XLOOKUP(D45,Lookup_Departments!$A$2:$A$7,Lookup_Departments!$B$2:$B$7,"Invalid Dept_Code",0) -> Information Technology | F45: 43686 | G45: =TEXT(Table1[[#This Row],[Hire Date ]],"yyyy") -> 2019 | H45: 81896 | I45: 79 | J45: =DATEDIF(F45,TODAY(),"Y") -> 6 | K45: {=_xlfn.IFS(I45<=49,"Needs Improvement",I45<=69,"Developing",I45<=84,"Achieving",I45<=94,"Exceeding",I45<=100,"Outstanding")} -> Achieving | L45: =_xlfn.XLOOKUP(K45,Lookup_Performance!$C$2:$C$6,Lookup_Performance!$D$2:$D$6,"N/A",0) -> 0.05 | M45: =H45*L45 -> 4094.8 | N45: Resigned | O45: =TRIM(CLEAN(Table1[[#This Row],[Employment Status]])) -> Resigned
B46: EMP077 | C46: Amanda Lopez | D46: SAL05 | E46: =_xlfn.XLOOKUP(D46,Lookup_Departments!$A$2:$A$7,Lookup_Departments!$B$2:$B$7,"Invalid Dept_Code",0) -> Sales | F46: 07/14/2016 | G46: =TEXT(Table1[[#This Row],[Hire Date ]],"yyyy") -> 2016 | H46: 78402 | I46: 54 | J46: =DATEDIF(F46,TODAY(),"Y") -> 9 | K46: {=_xlfn.IFS(I46<=49,"Needs Improvement",I46<=69,"Developing",I46<=84,"Achieving",I46<=94,"Exceeding",I46<=100,"Outstanding")} -> Developing | L46: =_xlfn.XLOOKUP(K46,Lookup_Performance!$C$2:$C$6,Lookup_Performance!$D$2:$D$6,"N/A",0) -> 0.02 | M46: =H46*L46 -> 1568.04 | N46: Active | O46: =TRIM(CLEAN(Table1[[#This Row],[Employment Status]])) -> Active
B47: EMP023 | C47: Thomas Lopez | D47: OPS06 | E47: =_xlfn.XLOOKUP(D47,Lookup_Departments!$A$2:$A$7,Lookup_Departments!$B$2:$B$7,"Invalid Dept_Code",0) -> Operations | F47: 42647 | G47: =TEXT(Table1[[#This Row],[Hire Date ]],"yyyy") -> 2016 | H47: 105498 | I47: 76 | J47: =DATEDIF(F47,TODAY(),"Y") -> 9 | K47: {=_xlfn.IFS(I47<=49,"Needs Improvement",I47<=69,"Developing",I47<=84,"Achieving",I47<=94,"Exceeding",I47<=100,"Outstanding")} -> Achieving | L47: =_xlfn.XLOOKUP(K47,Lookup_Performance!$C$2:$C$6,Lookup_Performance!$D$2:$D$6,"N/A",0) -> 0.05 | M47: =H47*L47 -> 5274.9 | N47: Active | O47: =TRIM(CLEAN(Table1[[#This Row],[Employment Status]])) -> Active
B48: EMP133 | C48: Melissa Johnson | D48: MKT04 | E48: =_xlfn.XLOOKUP(D48,Lookup_Departments!$A$2:$A$7,Lookup_Departments!$B$2:$B$7,"Invalid Dept_Code",0) -> Marketing | F48: 43656 | G48: =TEXT(Table1[[#This Row],[Hire Date ]],"yyyy") -> 2019 | H48: 91749 | I48: 72 | J48: =DATEDIF(F48,TODAY(),"Y") -> 7 | K48: {=_xlfn.IFS(I48<=49,"Needs Improvement",I48<=69,"Developing",I48<=84,"Achieving",I48<=94,"Exceeding",I48<=100,"Outstanding")} -> Achieving | L48: =_xlfn.XLOOKUP(K48,Lookup_Performance!$C$2:$C$6,Lookup_Performance!$D$2:$D$6,"N/A",0) -> 0.05 | M48: =H48*L48 -> 4587.45 | N48: Left | O48: =TRIM(CLEAN(Table1[[#This Row],[Employment Status]])) -> Left
B49: EMP141 | C49: Amanda Johnson | D49: OPS06 | E49: =_xlfn.XLOOKUP(D49,Lookup_Departments!$A$2:$A$7,Lookup_Departments!$B$2:$B$7,"Invalid Dept_Code",0) -> Operations | F49: 44437 | G49: =TEXT(Table1[[#This Row],[Hire Date ]],"yyyy") -> 2021 | H49: 99935 | I49: 84 | J49: =DATEDIF(F49,TODAY(),"Y") -> 4 | K49: {=_xlfn.IFS(I49<=49,"Needs Improvement",I49<=69,"Developing",I49<=84,"Achieving",I49<=94,"Exceeding",I49<=100,"Outstanding")} -> Achieving | L49: =_xlfn.XLOOKUP(K49,Lookup_Performance!$C$2:$C$6,Lookup_Performance!$D$2:$D$6,"N/A",0) -> 0.05 | M49: =H49*L49 -> 4996.75 | N49: Resigned | O49: =TRIM(CLEAN(Table1[[#This Row],[Employment Status]])) -> Resigned
B50: EMP012 | C50: John Davis | D50: IT02 | E50: =_xlfn.XLOOKUP(D50,Lookup_Departments!$A$2:$A$7,Lookup_Departments!$B$2:$B$7,"Invalid Dept_Code",0) -> Information Technology | F50: 42761 | G50: =TEXT(Table1[[#This Row],[Hire Date ]],"yyyy") -> 2017 | H50: 83531 | I50: 30 | J50: =DATEDIF(F50,TODAY(),"Y") -> 9 | K50: {=_xlfn.IFS(I50<=49,"Needs Improvement",I50<=69,"Developing",I50<=84,"Achieving",I50<=94,"Exceeding",I50<=100,"Outstanding")} -> Needs Improvement | L50: =_xlfn.XLOOKUP(K50,Lookup_Performance!$C$2:$C$6,Lookup_Performance!$D$2:$D$6,"N/A",0) -> 0 | M50: =H50*L50 -> 0 | N50: Left | O50: =TRIM(CLEAN(Table1[[#This Row],[Employment Status]])) -> Left
B51: EMP080 | C51: James Johnson | D51: MKT04 | E51: =_xlfn.XLOOKUP(D51,Lookup_Departments!$A$2:$A$7,Lookup_Departments!$B$2:$B$7,"Invalid Dept_Code",0) -> Marketing | F51: 43981 | G51: =TEXT(Table1[[#This Row],[Hire Date ]],"yyyy") -> 2020 | H51: 75023 | I51: 68 | J51: =DATEDIF(F51,TODAY(),"Y") -> 6 | K51: {=_xlfn.IFS(I51<=49,"Needs Improvement",I51<=69,"Developing",I51<=84,"Achieving",I51<=94,"Exceeding",I51<=100,"Outstanding")} -> Developing | L51: =_xlfn.XLOOKUP(K51,Lookup_Performance!$C$2:$C$6,Lookup_Performance!$D$2:$D$6,"N/A",0) -> 0.02 | M51: =H51*L51 -> 1500.46 | N51: Active | O51: =TRIM(CLEAN(Table1[[#This Row],[Employment Status]])) -> Active
B52: EMP069 | C52: Jane Davis | D52: HR01 | E52: =_xlfn.XLOOKUP(D52,Lookup_Departments!$A$2:$A$7,Lookup_Departments!$B$2:$B$7,"Invalid Dept_Code",0) -> Human Resources | F52: 44612 | G52: =TEXT(Table1[[#This Row],[Hire Date ]],"yyyy") -> 2022 | H52: 93290 | I52: 53 | J52: =DATEDIF(F52,TODAY(),"Y") -> 4 | K52: {=_xlfn.IFS(I52<=49,"Needs Improvement",I52<=69,"Developing",I52<=84,"Achieving",I52<=94,"Exceeding",I52<=100,"Outstanding")} -> Developing | L52: =_xlfn.XLOOKUP(K52,Lookup_Performance!$C$2:$C$6,Lookup_Performance!$D$2:$D$6,"N/A",0) -> 0.02 | M52: =H52*L52 -> 1865.8 | N52: Active | O52: =TRIM(CLEAN(Table1[[#This Row],[Employment Status]])) -> Active
B53: EMP150 | C53: Richard Davis | D53: OPS06 | E53: =_xlfn.XLOOKUP(D53,Lookup_Departments!$A$2:$A$7,Lookup_Departments!$B$2:$B$7,"Invalid Dept_Code",0) -> Operations | F53: 42628 | G53: =TEXT(Table1[[#This Row],[Hire Date ]],"yyyy") -> 2016 | H53: 115527 | I53: 63 | J53: =DATEDIF(F53,TODAY(),"Y") -> 9 | K53: {=_xlfn.IFS(I53<=49,"Needs Improvement",I53<=69,"Developing",I53<=84,"Achieving",I53<=94,"Exceeding",I53<=100,"Outstanding")} -> Developing | L53: =_xlfn.XLOOKUP(K53,Lookup_Performance!$C$2:$C$6,Lookup_Performance!$D$2:$D$6,"N/A",0) -> 0.02 | M53: =H53*L53 -> 2310.54 | N53: Resigned | O53: =TRIM(CLEAN(Table1[[#This Row],[Employment Status]])) -> Resigned
B54: EMP028 | C54: Thomas Rodriguez | D54: FIN03 | E54: =_xlfn.XLOOKUP(D54,Lookup_Departments!$A$2:$A$7,Lookup_Departments!$B$2:$B$7,"Invalid Dept_Code",0) -> Finance | F54: 10/07/2019 | G54: =TEXT(Table1[[#This Row],[Hire Date ]],"yyyy") -> 2019 | H54: 55920 | I54: 84 | J54: =DATEDIF(F54,TODAY(),"Y") -> 6 | K54: {=_xlfn.IFS(I54<=49,"Needs Improvement",I54<=69,"Developing",I54<=84,"Achieving",I54<=94,"Exceeding",I54<=100,"Outstanding")} -> Achieving | L54: =_xlfn.XLOOKUP(K54,Lookup_Performance!$C$2:$C$6,Lookup_Performance!$D$2:$D$6,"N/A",0) -> 0.05 | M54: =H54*L54 -> 2796 | N54: Active | O54: =TRIM(CLEAN(Table1[[#This Row],[Employment Status]])) -> Active
B55: EMP087 | C55: Emily Johnson | D55: SAL05 | E55: =_xlfn.XLOOKUP(D55,Lookup_Departments!$A$2:$A$7,Lookup_Departments!$B$2:$B$7,"Invalid Dept_Code",0) -> Sales | F55: 43464 | G55: =TEXT(Table1[[#This Row],[Hire Date ]],"yyyy") -> 2018 | H55: 80189 | I55: 30 | J55: =DATEDIF(F55,TODAY(),"Y") -> 7 | K55: {=_xlfn.IFS(I55<=49,"Needs Improvement",I55<=69,"Developing",I55<=84,"Achieving",I55<=94,"Exceeding",I55<=100,"Outstanding")} -> Needs Improvement | L55: =_xlfn.XLOOKUP(K55,Lookup_Performance!$C$2:$C$6,Lookup_Performance!$D$2:$D$6,"N/A",0) -> 0 | M55: =H55*L55 -> 0 | N55: Active | O55: =TRIM(CLEAN(Table1[[#This Row],[Employment Status]])) -> Active
B56: EMP119 | C56: Emily Garcia | D56: HR01 | E56: =_xlfn.XLOOKUP(D56,Lookup_Departments!$A$2:$A$7,Lookup_Departments!$B$2:$B$7,"Invalid Dept_Code",0) -> Human Resources | F56: 44189 | G56: =TEXT(Table1[[#This Row],[Hire Date ]],"yyyy") -> 2020 | H56: 118947 | I56: 96 | J56: =DATEDIF(F56,TODAY(),"Y") -> 5 | K56: {=_xlfn.IFS(I56<=49,"Needs Improvement",I56<=69,"Developing",I56<=84,"Achieving",I56<=94,"Exceeding",I56<=100,"Outstanding")} -> Outstanding | L56: =_xlfn.XLOOKUP(K56,Lookup_Performance!$C$2:$C$6,Lookup_Performance!$D$2:$D$6,"N/A",0) -> 0.12 | M56: =H56*L56 -> 14273.64 | N56: Active | O56: =TRIM(CLEAN(Table1[[#This Row],[Employment Status]])) -> Active
B57: EMP042 | C57: Jane Anderson | D57: IT02 | E57: =_xlfn.XLOOKUP(D57,Lookup_Departments!$A$2:$A$7,Lookup_Departments!$B$2:$B$7,"Invalid Dept_Code",0) -> Information Technology | F57: 45112 | G57: =TEXT(Table1[[#This Row],[Hire Date ]],"yyyy") -> 2023 | H57: 74560 | I57: 54 | J57: =DATEDIF(F57,TODAY(),"Y") -> 3 | K57: {=_xlfn.IFS(I57<=49,"Needs Improvement",I57<=69,"Developing",I57<=84,"Achieving",I57<=94,"Exceeding",I57<=100,"Outstanding")} -> Developing | L57: =_xlfn.XLOOKUP(K57,Lookup_Performance!$C$2:$C$6,Lookup_Performance!$D$2:$D$6,"N/A",0) -> 0.02 | M57: =H57*L57 -> 1491.2 | N57: Active | O57: =TRIM(CLEAN(Table1[[#This Row],[Employment Status]])) -> Active
B58: EMP005 | C58: Thomas Garcia | D58: OPS06 | E58: =_xlfn.XLOOKUP(D58,Lookup_Departments!$A$2:$A$7,Lookup_Departments!$B$2:$B$7,"Invalid Dept_Code",0) -> Operations | F58: 44148 | G58: =TEXT(Table1[[#This Row],[Hire Date ]],"yyyy") -> 2020 | H58: 75808 | I58: 75 | J58: =DATEDIF(F58,TODAY(),"Y") -> 5 | K58: {=_xlfn.IFS(I58<=49,"Needs Improvement",I58<=69,"Developing",I58<=84,"Achieving",I58<=94,"Exceeding",I58<=100,"Outstanding")} -> Achieving | L58: =_xlfn.XLOOKUP(K58,Lookup_Performance!$C$2:$C$6,Lookup_Performance!$D$2:$D$6,"N/A",0) -> 0.05 | M58: =H58*L58 -> 3790.4 | N58: Active | O58: =TRIM(CLEAN(Table1[[#This Row],[Employment Status]])) -> Active
B59: EMP033 | C59: David Martinez | D59: HR01 | E59: =_xlfn.XLOOKUP(D59,Lookup_Departments!$A$2:$A$7,Lookup_Departments!$B$2:$B$7,"Invalid Dept_Code",0) -> Human Resources | F59: 02/07/2018 | G59: =TEXT(Table1[[#This Row],[Hire Date ]],"yyyy") -> 2018 | H59: 91655 | I59: 95 | J59: =DATEDIF(F59,TODAY(),"Y") -> 8 | K59: {=_xlfn.IFS(I59<=49,"Needs Improvement",I59<=69,"Developing",I59<=84,"Achieving",I59<=94,"Exceeding",I59<=100,"Outstanding")} -> Outstanding | L59: =_xlfn.XLOOKUP(K59,Lookup_Performance!$C$2:$C$6,Lookup_Performance!$D$2:$D$6,"N/A",0) -> 0.12 | M59: =H59*L59 -> 10998.6 | N59: Active | O59: =TRIM(CLEAN(Table1[[#This Row],[Employment Status]])) -> Active
B60: EMP061 | C60: Emily Brown | D60: IT02 | E60: =_xlfn.XLOOKUP(D60,Lookup_Departments!$A$2:$A$7,Lookup_Departments!$B$2:$B$7,"Invalid Dept_Code",0) -> Information Technology | F60: 45255 | G60: =TEXT(Table1[[#This Row],[Hire Date ]],"yyyy") -> 2023 | H60: 49435 | I60: 68 | J60: =DATEDIF(F60,TODAY(),"Y") -> 2 | K60: {=_xlfn.IFS(I60<=49,"Needs Improvement",I60<=69,"Developing",I60<=84,"Achieving",I60<=94,"Exceeding",I60<=100,"Outstanding")} -> Developing | L60: =_xlfn.XLOOKUP(K60,Lookup_Performance!$C$2:$C$6,Lookup_Performance!$D$2:$D$6,"N/A",0) -> 0.02 | M60: =H60*L60 -> 988.7 | N60: Left | O60: =TRIM(CLEAN(Table1[[#This Row],[Employment Status]])) -> Left
B61: EMP102 | C61: Emily Wilson | D61: SAL05 | E61: =_xlfn.XLOOKUP(D61,Lookup_Departments!$A$2:$A$7,Lookup_Departments!$B$2:$B$7,"Invalid Dept_Code",0) -> Sales | F61: 45217 | G61: =TEXT(Table1[[#This Row],[Hire Date ]],"yyyy") -> 2023 | H61: 110381 | I61: 93 | J61: =DATEDIF(F61,TODAY(),"Y") -> 2 | K61: {=_xlfn.IFS(I61<=49,"Needs Improvement",I61<=69,"Developing",I61<=84,"Achieving",I61<=94,"Exceeding",I61<=100,"Outstanding")} -> Exceeding | L61: =_xlfn.XLOOKUP(K61,Lookup_Performance!$C$2:$C$6,Lookup_Performance!$D$2:$D$6,"N/A",0) -> 0.08 | M61: =H61*L61 -> 8830.48 | N61: Active | O61: =TRIM(CLEAN(Table1[[#This Row],[Employment Status]])) -> Active
B62: EMP067 | C62: Michael Anderson | D62: HR01 | E62: =_xlfn.XLOOKUP(D62,Lookup_Departments!$A$2:$A$7,Lookup_Departments!$B$2:$B$7,"Invalid Dept_Code",0) -> Human Resources | F62: 44079 | G62: =TEXT(Table1[[#This Row],[Hire Date ]],"yyyy") -> 2020 | H62: 114748 | I62: 33 | J62: =DATEDIF(F62,TODAY(),"Y") -> 5 | K62: {=_xlfn.IFS(I62<=49,"Needs Improvement",I62<=69,"Developing",I62<=84,"Achieving",I62<=94,"Exceeding",I62<=100,"Outstanding")} -> Needs Improvement | L62: =_xlfn.XLOOKUP(K62,Lookup_Performance!$C$2:$C$6,Lookup_Performance!$D$2:$D$6,"N/A",0) -> 0 | M62: =H62*L62 -> 0 | N62: Active | O62: =TRIM(CLEAN(Table1[[#This Row],[Employment Status]])) -> Active
B63: EMP017 | C63: Robert Johnson | D63: OPS06 | E63: =_xlfn.XLOOKUP(D63,Lookup_Departments!$A$2:$A$7,Lookup_Departments!$B$2:$B$7,"Invalid Dept_Code",0) -> Operations | F63: 42800 | G63: =TEXT(Table1[[#This Row],[Hire Date ]],"yyyy") -> 2017 | H63: 63302 | I63: 91 | J63: =DATEDIF(F63,TODAY(),"Y") -> 9 | K63: {=_xlfn.IFS(I63<=49,"Needs Improvement",I63<=69,"Developing",I63<=84,"Achieving",I63<=94,"Exceeding",I63<=100,"Outstanding")} -> Exceeding | L63: =_xlfn.XLOOKUP(K63,Lookup_Performance!$C$2:$C$6,Lookup_Performance!$D$2:$D$6,"N/A",0) -> 0.08 | M63: =H63*L63 -> 5064.16 | N63: Active | O63: =TRIM(CLEAN(Table1[[#This Row],[Employment Status]])) -> Active
B64: EMP123 | C64: Robert Miller | D64: IT02 | E64: =_xlfn.XLOOKUP(D64,Lookup_Departments!$A$2:$A$7,Lookup_Departments!$B$2:$B$7,"Invalid Dept_Code",0) -> Information Technology | F64: 42122 | G64: =TEXT(Table1[[#This Row],[Hire Date ]],"yyyy") -> 2015 | H64: 75519 | I64: 64 | J64: =DATEDIF(F64,TODAY(),"Y") -> 11 | K64: {=_xlfn.IFS(I64<=49,"Needs Improvement",I64<=69,"Developing",I64<=84,"Achieving",I64<=94,"Exceeding",I64<=100,"Outstanding")} -> Developing | L64: =_xlfn.XLOOKUP(K64,Lookup_Performance!$C$2:$C$6,Lookup_Performance!$D$2:$D$6,"N/A",0) -> 0.02 | M64: =H64*L64 -> 1510.38 | N64: Active | O64: =TRIM(CLEAN(Table1[[#This Row],[Employment Status]])) -> Active
...

Sheet Lookup_Departments
A1: Dept_Code | B1: Department_Name
A2: HR01 | B2: Human Resources
A3: IT02 | B3: Information Technology
A4: FIN03 | B4: Finance
A5: MKT04 | B5: Marketing
A6: SAL05 | B6: Sales
A7: OPS06 | B7: Operations

Sheet Lookup_Performance
A1: Min_Score | B1: Max_Score | C1: Performance_Band | D1: Bonus_Percentage
A2: 0 | B2: 49 | C2: Needs Improvement | D2: 0
A3: 50 | B3: 69 | C3: Developing | D3: 0.02
A4: 70 | B4: 84 | C4: Achieving | D4: 0.05
A5: 85 | B5: 94 | C5: Exceeding | D5: 0.08
A6: 95 | B6: 100 | C6: Outstanding | D6: 0.12

Sheet Analysis
B1: Headcount & Salary
B3: Count of Emp ID | D3: Average of Salary
B4: 150 | C4: =GETPIVOTDATA("[Measures].[Count of Emp ID]",$B$3) -> 150 | D4: 83341.107 | E4: =GETPIVOTDATA("[Measures].[Average of Salary]",$D$3) -> 83341.107
B8: Departments | C8: No. of Headcount | E8: Departments | F8: Average of Salary
B9: Finance | C9: 17 | E9: Finance | F9: 89240.235
B10: Human Resources | C10: 18 | E10: Human Resources | F10: 85688.778
B11: Information Technology | C11: 36 | E11: Information Technology | F11: 79256.722
B12: Marketing | C12: 19 | E12: Marketing | F12: 85675.579
B13: Operations | C13: 29 | E13: Operations | F13: 79512.276
B14: Sales | C14: 31 | E14: Sales | F14: 85637.097
B15: Grand Total | C15: 150 | E15: Grand Total | F15: 83341.107
C17: Attrition Rate
B20: Employment Status | C20: Headcounts | E20: Department with highest | F20: No. of Headcounts | H20: Department with highest | I20: No. of Headcounts
B21: Active | C21: 116 | E21: Departments | F21: Active | H21: Departments | I21: Active | J21: Left | K21: Resigned
B22: Left | C22: 24 | E22: Sales | F22: 25 | H22: Sales | I22: 25 | J22: 4 | K22: 2
B23: Resigned | C23: 10 | E23: Grand Total | F23: 25 | H23: Grand Total | I23: 25 | J23: 4 | K23: 2
B24: Grand Total | C24: 150
B28: Count of Emp ID | C28: Column Labels | G28: Count of Emp ID | H28: Column Labels
B29: Row Labels | C29: Active | D29: Left | E29: Resigned | G29: Row Labels | H29: Active | I29: Left | J29: Resigned | K29: Grand Total
B30: Finance | C30: 14 | D30: 3 | G30: Finance | H30: 0.82352941 | I30: 0.17647059 | J30: 0 | K30: 1
B31: Human Resources | C31: 15 | D31: 2 | E31: 1 | G31: Human Resources | H31: 0.83333333 | I31: 0.11111111 | J31: 0.055555556 | K31: 1
B32: Information Technology | C32: 28 | D32: 6 | E32: 2 | G32: Information Technology | H32: 0.77777778 | I32: 0.16666667 | J32: 0.055555556 | K32: 1
B33: Marketing | C33: 16 | D33: 3 | G33: Marketing | H33: 0.84210526 | I33: 0.15789474 | J33: 0 | K33: 1
B34: Operations | C34: 18 | D34: 6 | E34: 5 | G34: Operations | H34: 0.62068966 | I34: 0.20689655 | J34: 0.17241379 | K34: 1
B35: Sales | C35: 25 | D35: 4 | E35: 2 | G35: Sales | H35: 0.80645161 | I35: 0.12903226 | J35: 0.064516129 | K35: 1
B36: Grand Total | C36: 116 | D36: 24 | E36: 10 | G36: Grand Total | H36: 0.77333333 | I36: 0.16 | J36: 0.066666667 | K36: 1 | L36: =GETPIVOTDATA("[Measures].[Count of Emp ID]",$G$28,"[Table1].[Employment Status]","[Table1].[Employment Status].&[Left]") -> 0.16
B41: Performance by Status
B43: Department | C43: Avg. Performance Score
B44: Human Resources | C44: 71 | H44: Row Labels | I44: Count of Emp ID
B45: Marketing | C45: 73.210526 | H45: Achieving | I45: 0.27333333
B46: Grand Total | C46: 72.135135 | E46: Performance Band | F46: Bonus Payout | H46: Developing | I46: 0.32666667
E47: Needs Improvement | F47: 0 | H47: Exceeding | I47: 0.14666667
E48: Developing | F48: 84484.2 | H48: Needs Improvement | I48: 0.18666667
B49: Row Labels | C49: Avg. Performance Score | E49: Outstanding | F49: 91326.24 | H49: Outstanding | I49: 0.066666667
B50: Finance | C50: 68.941176 | E50: Exceeding | F50: 144880.48 | H50: Grand Total | I50: 1
B51: Human Resources | C51: 71 | E51: Achieving | F51: 164690.8
B52: Information Technology | C52: 65.388889 | E52: Grand Total | F52: 485381.72
B53: Marketing | C53: 73.210526
B54: Operations | C54: 69.931034
B55: Sales | C55: 64.129032
...

Sheet HR_Dashboard_Workforce

Sheet HR_Dashboard_Performance
